2021-02-03 09:53:45,703 ERROR: Exception on /api/token [POST] [in C:\Users\vpf26432\Anaconda3\envs\hancock\lib\site-packages\flask\app.py:1891]]
Traceback (most recent call last):
  File "C:\Users\vpf26432\Anaconda3\envs\hancock\lib\site-packages\redis\connection.py", line 559, in connect
    sock = self._connect()
  File "C:\Users\vpf26432\Anaconda3\envs\hancock\lib\site-packages\redis\connection.py", line 584, in _connect
    for res in socket.getaddrinfo(self.host, self.port, self.socket_type,
  File "C:\Users\vpf26432\Anaconda3\envs\hancock\lib\socket.py", line 918, in getaddrinfo
    for res in _socket.getaddrinfo(host, port, family, type, proto, flags):
socket.gaierror: [Errno 11002] getaddrinfo failed

During handling of the above exception, another exception occurred:

Traceback (most recent call last):
  File "C:\Users\vpf26432\Anaconda3\envs\hancock\lib\site-packages\flask\app.py", line 1950, in full_dispatch_request
    rv = self.dispatch_request()
  File "C:\Users\vpf26432\Anaconda3\envs\hancock\lib\site-packages\flask\app.py", line 1936, in dispatch_request
    return self.view_functions[rule.endpoint](**req.view_args)
  File "C:\Users\vpf26432\Anaconda3\envs\hancock\lib\site-packages\flask_restx\api.py", line 375, in wrapper
    resp = resource(*args, **kwargs)
  File "C:\Users\vpf26432\Anaconda3\envs\hancock\lib\site-packages\flask\views.py", line 89, in view
    return self.dispatch_request(*args, **kwargs)
  File "C:\Users\vpf26432\Anaconda3\envs\hancock\lib\site-packages\flask_restx\resource.py", line 44, in dispatch_request
    resp = meth(*args, **kwargs)
  File "C:\Users\vpf26432\Anaconda3\envs\hancock\lib\site-packages\flask_restx\marshalling.py", line 248, in wrapper
    resp = f(*args, **kwargs)
  File "C:\Users\vpf26432\PycharmProjects\hancock\hancock\routes.py", line 41, in post
    revoked_store.set(access_jti, 'false', ACCESS_EXPIRES * 1.2)
  File "C:\Users\vpf26432\Anaconda3\envs\hancock\lib\site-packages\redis\client.py", line 1801, in set
    return self.execute_command('SET', *pieces)
  File "C:\Users\vpf26432\Anaconda3\envs\hancock\lib\site-packages\redis\client.py", line 898, in execute_command
    conn = self.connection or pool.get_connection(command_name, **options)
  File "C:\Users\vpf26432\Anaconda3\envs\hancock\lib\site-packages\redis\connection.py", line 1192, in get_connection
    connection.connect()
  File "C:\Users\vpf26432\Anaconda3\envs\hancock\lib\site-packages\redis\connection.py", line 563, in connect
    raise ConnectionError(self._error_message(e))
redis.exceptions.ConnectionError: Error 11002 connecting to redis:6379. getaddrinfo failed.
